Workbook
Name UPDATE: '[1]Data Sheet'!$E$1

Sheet Historical Financials
A13: Historical Financials -->>

Sheet Consol. Historical FS
B2: CONSOLIDATED HISTORICAL FINANCIAL STATEMENTS
B3: ₹'cr, unless otherwise stated | C3: FY21A | D3: FY22A | E3: FY23A | F3: FY24A | G3: FY25A
A5: # | B5: Profit & Loss Statement
B7: Revenue from Operations | C7: 12549.6 | D7: 17118.79 | E7: 20851.91 | F7: 26710.56 | G7: 30475.33
B8: Other Operating Revenues | C8: 0 | D8: 0 | E8: 0 | F8: 0 | G8: 0
B9: Total Revenue | C9: =ROUND(SUM(C7:C8),2) -> 12549.6 | D9: =ROUND(SUM(D7:D8),2) -> 17118.79 | E9: =ROUND(SUM(E7:E8),2) -> 20851.91 | F9: =ROUND(SUM(F7:F8),2) -> 26710.56 | G9: =ROUND(SUM(G7:G8),2) -> 30475.33
B10: Operating Expenses | C10: 3259.49 | D10: 4865.11 | E10: 5654.56 | F10: 7116.34 | G10: 8069.75
B13: Gross Profit | C13: =ROUND(C9-SUM(C10:C10),2) -> 9290.11 | D13: =ROUND(D9-SUM(D10:D10),2) -> 12253.68 | E13: =ROUND(E9-SUM(E10:E10),2) -> 15197.35 | F13: =ROUND(F9-SUM(F10:F10),2) -> 19594.22 | G13: =ROUND(G9-SUM(G10:G10),2) -> 22405.58
B14: Employee Benefits Expense | C14: 615.05 | D14: 779.43 | E14: 1178.17 | F14: 1896.4 | G14: 2008.66
B15: Loss on fair valuation of Compulsorily Convertible Preference Shares | C15: 0 | D15: 0 | E15: 0 | F15: 0 | G15: 0
B16: Other Expenses | C16: =691.62-715.24 -> -23.62 | D16: =1077.74+872.07 -> 1949.81 | E16: =1185.73+1886.32 -> 3072.05 | F16: =1833.9+112.82 -> 1946.72 | G16: =1975.55+280.85 -> 2256.4
B17: EBITDA | C17: =ROUND(C13-SUM(C14:C16),2) -> 8698.68 | D17: =ROUND(D13-SUM(D14:D16),2) -> 9524.44 | E17: =ROUND(E13-SUM(E14:E16),2) -> 10947.13 | F17: =ROUND(F13-SUM(F14:F16),2) -> 15751.1 | G17: =ROUND(G13-SUM(G14:G16),2) -> 18140.52
B18: Depreciation and Amortisation Expense | C18: 2107.34 | D18: 3099.3 | E18: 3423.24 | F18: 3888.46 | G18: 4378.93
B19: EBIT | C19: =ROUND(C17-C18,2) -> 6591.34 | D19: =ROUND(D17-D18,2) -> 6425.14 | E19: =ROUND(E17-E18,2) -> 7523.89 | F19: =ROUND(F17-F18,2) -> 11862.64 | G19: =ROUND(G17-G18,2) -> 13761.59
B20: Finance Costs | C20: =2129.16+126.13 -> 2255.29 | D20: =2559.61-15.69 -> 2543.92 | E20: =2593.62-230.98 -> 2362.64 | F20: =2784.41-51.47 -> 2732.94 | G20: =2778-246.18 -> 2531.82
B21: Other Income | C21: 1970.23 | D21: 2223.72 | E21: 1553.48 | F21: 1499.42 | G21: =1304.48+603.27 -> 1907.75
B22: Profit before share of Profit / (Loss) of Associate / Joint Ventures | C22: =ROUND(C19-C20+C21,2) -> 6306.28 | D22: =ROUND(D19-D20+D21,2) -> 6104.94 | E22: =ROUND(E19-E20+E21,2) -> 6714.73 | F22: =ROUND(F19-F20+F21,2) -> 10629.12 | G22: =ROUND(G19-G20+G21,2) -> 13137.52
B23: Share of Profit / (Loss) from Associate /Joint Ventures (net of tax) | C23: -14.27 | D23: 17.39 | E23: 47.78 | F23: -161.69 | G23: 141.56
B24: Profit before Exceptional Items and Tax | C24: =ROUND(SUM(C22:C23),2) -> 6292.01 | D24: =ROUND(SUM(D22:D23),2) -> 6122.33 | E24: =ROUND(SUM(E22:E23),2) -> 6762.51 | F24: =ROUND(SUM(F22:F23),2) -> 10467.43 | G24: =ROUND(SUM(G22:G23),2) -> 13279.08
B25: Exceptional Items | C25: 0 | D25: -405.19 | E25: -1273.38 | F25: -373.7 | G25: -249.46
B26: Profit before Tax | C26: =ROUND(SUM(C24:C25),2) -> 6292.01 | D26: =ROUND(SUM(D24:D25),2) -> 5717.14 | E26: =ROUND(SUM(E24:E25),2) -> 5489.13 | F26: =ROUND(SUM(F24:F25),2) -> 10093.73 | G26: =ROUND(SUM(G24:G25),2) -> 13029.62
B27: Current Tax | C27: 1271.51 | D27: 888.2 | E27: 977.9 | F27: 1134.73 | G27: 2221.87
B28: Adjustment of tax relating to earlier years | C28: -130.63 | D28: 0 | E28: 0 | F28: 455.16 | G28: 0
B29: Deferred Tax | C29: 102.39 | D29: -124.24 | E29: -881.52 | F29: 399.85 | G29: -253.51
B30: Net profit from continuing operations | C30: =ROUND(C26-SUM(C27:C29),2) -> 5048.74 | D30: =ROUND(D26-SUM(D27:D29),2) -> 4953.18 | E30: =ROUND(E26-SUM(E27:E29),2) -> 5392.75 | F30: =ROUND(F26-SUM(F27:F29),2) -> 8103.99 | G30: =ROUND(G26-SUM(G27:G29),2) -> 11061.26
B31: Profit before tax from discontinued operations | C31: 0 | D31: 0 | E31: 0 | F31: 0 | G31: 0
B32: Tax income / (expense) of discontinued operations | C32: 0 | D32: 0 | E32: 0 | F32: 0 | G32: 0
B33: Net profit from discontinuing operations | C33: =ROUND(SUM(C31:C32),2) -> 0 | D33: =ROUND(SUM(D31:D32),2) -> 0 | E33: =ROUND(SUM(E31:E32),2) -> 0 | F33: =ROUND(SUM(F31:F32),2) -> 0 | G33: =ROUND(SUM(G31:G32),2) -> 0
B34: Net Profit | C34: =ROUND(SUM(C30,C33),2) -> 5048.74 | D34: =ROUND(SUM(D30,D33),2) -> 4953.18 | E34: =ROUND(SUM(E30,E33),2) -> 5392.75 | F34: =ROUND(SUM(F30,F33),2) -> 8103.99 | G34: =ROUND(SUM(G30,G33),2) -> 11061.26
B35: Net Profit attributable to:
B36: Owners of the company | C36: 4994.3 | D36: 4886.03 | E36: 5310.18 | F36: 8110.64 | G36: 11092.31
B37: Non-Controlling Interest | C37: 54.44 | D37: 67.15 | E37: 82.57 | F37: -6.65 | G37: -31.05
A39: # | B39: Balance Sheet
B41: ASSETS
B42: Non-current Assets
B43: Property, Plant and Equipment | C43: 36791.51 | D43: 41488.7 | E43: 48414 | F43: 51803.83 | G43: 62394.43
B44: Right of Use Assets | C44: 1775.95 | D44: 2772.25 | E44: 3541.9 | F44: 3809.11 | G44: 6177.54
B45: Capital work-in-progress | C45: 3697.13 | D45: 4022.9 | E45: 6814.03 | F45: 10936.09 | G45: 11592.19
B46: Investment Property | C46: 0 | D46: 0 | E46: 2473.38 | F46: 1345.3 | G46: 1459.16
B47: Goodwill | C47: 4036.43 | D47: 6711.43 | E47: 6963.4 | F47: 6906.93 | G47: 7093.59
...

Sheet Consol. Common Size FS
B2: COMMON SIZE FINANCIAL STATEMENTS
C3: ='Consol. Historical FS'!C3 -> FY21A | D3: ='Consol. Historical FS'!D3 -> FY22A | E3: ='Consol. Historical FS'!E3 -> FY23A | F3: ='Consol. Historical FS'!F3 -> FY24A | G3: ='Consol. Historical FS'!G3 -> FY25A
A5: # | B5: Profit & Loss Statement - as a % of Total Revenue
B7: Revenue from Operations | C7: =ROUND('Consol. Historical FS'!C7/'Consol. Historical FS'!C$9,3) -> 1 | D7: =ROUND('Consol. Historical FS'!D7/'Consol. Historical FS'!D$9,3) -> 1 | E7: =ROUND('Consol. Historical FS'!E7/'Consol. Historical FS'!E$9,3) -> 1 | F7: =ROUND('Consol. Historical FS'!F7/'Consol. Historical FS'!F$9,3) -> 1 | G7: =ROUND('Consol. Historical FS'!G7/'Consol. Historical FS'!G$9,3) -> 1
B8: Other Operating Revenues | C8: =ROUND('Consol. Historical FS'!C8/'Consol. Historical FS'!C$9,3) -> 0 | D8: =ROUND('Consol. Historical FS'!D8/'Consol. Historical FS'!D$9,3) -> 0 | E8: =ROUND('Consol. Historical FS'!E8/'Consol. Historical FS'!E$9,3) -> 0 | F8: =ROUND('Consol. Historical FS'!F8/'Consol. Historical FS'!F$9,3) -> 0 | G8: =ROUND('Consol. Historical FS'!G8/'Consol. Historical FS'!G$9,3) -> 0
B9: Total Revenue | C9: =ROUND('Consol. Historical FS'!C9/'Consol. Historical FS'!C$9,3) -> 1 | D9: =ROUND('Consol. Historical FS'!D9/'Consol. Historical FS'!D$9,3) -> 1 | E9: =ROUND('Consol. Historical FS'!E9/'Consol. Historical FS'!E$9,3) -> 1 | F9: =ROUND('Consol. Historical FS'!F9/'Consol. Historical FS'!F$9,3) -> 1 | G9: =ROUND('Consol. Historical FS'!G9/'Consol. Historical FS'!G$9,3) -> 1
B10: Operating Expenses | C10: ='Consol. Historical FS'!C10/'Consol. Historical FS'!C$7 -> 0.2597286 | D10: =ROUND('Consol. Historical FS'!D10/'Consol. Historical FS'!D$9,3) -> 0.284 | E10: =ROUND('Consol. Historical FS'!E10/'Consol. Historical FS'!E$9,3) -> 0.271 | F10: =ROUND('Consol. Historical FS'!F10/'Consol. Historical FS'!F$9,3) -> 0.266 | G10: =ROUND('Consol. Historical FS'!G10/'Consol. Historical FS'!G$9,3) -> 0.265
B11: Gross Profit | C11: =ROUND('Consol. Historical FS'!C13/'Consol. Historical FS'!C$9,3) -> 0.74 | D11: =ROUND('Consol. Historical FS'!D13/'Consol. Historical FS'!D$9,3) -> 0.716 | E11: =ROUND('Consol. Historical FS'!E13/'Consol. Historical FS'!E$9,3) -> 0.729 | F11: =ROUND('Consol. Historical FS'!F13/'Consol. Historical FS'!F$9,3) -> 0.734 | G11: =ROUND('Consol. Historical FS'!G13/'Consol. Historical FS'!G$9,3) -> 0.735
B12: Employee Benefits Expense | C12: =ROUND('Consol. Historical FS'!C14/'Consol. Historical FS'!C$9,3) -> 0.049 | D12: =ROUND('Consol. Historical FS'!D14/'Consol. Historical FS'!D$9,3) -> 0.046 | E12: =ROUND('Consol. Historical FS'!E14/'Consol. Historical FS'!E$9,3) -> 0.057 | F12: =ROUND('Consol. Historical FS'!F14/'Consol. Historical FS'!F$9,3) -> 0.071 | G12: =ROUND('Consol. Historical FS'!G14/'Consol. Historical FS'!G$9,3) -> 0.066
B13: Loss on fair valuation of Compulsorily Convertible Preference Shares | C13: =ROUND('Consol. Historical FS'!C15/'Consol. Historical FS'!C$9,3) -> 0 | D13: =ROUND('Consol. Historical FS'!D15/'Consol. Historical FS'!D$9,3) -> 0 | E13: =ROUND('Consol. Historical FS'!E15/'Consol. Historical FS'!E$9,3) -> 0 | F13: =ROUND('Consol. Historical FS'!F15/'Consol. Historical FS'!F$9,3) -> 0 | G13: =ROUND('Consol. Historical FS'!G15/'Consol. Historical FS'!G$9,3) -> 0
B14: Other Expenses | C14: =ROUND('Consol. Historical FS'!C16/'Consol. Historical FS'!C$9,3) -> -0.002 | D14: =ROUND('Consol. Historical FS'!D16/'Consol. Historical FS'!D$9,3) -> 0.114 | E14: =ROUND('Consol. Historical FS'!E16/'Consol. Historical FS'!E$9,3) -> 0.147 | F14: =ROUND('Consol. Historical FS'!F16/'Consol. Historical FS'!F$9,3) -> 0.073 | G14: =ROUND('Consol. Historical FS'!G16/'Consol. Historical FS'!G$9,3) -> 0.074
B15: EBITDA | C15: =ROUND('Consol. Historical FS'!C17/'Consol. Historical FS'!C$9,3) -> 0.693 | D15: =ROUND('Consol. Historical FS'!D17/'Consol. Historical FS'!D$9,3) -> 0.556 | E15: =ROUND('Consol. Historical FS'!E17/'Consol. Historical FS'!E$9,3) -> 0.525 | F15: =ROUND('Consol. Historical FS'!F17/'Consol. Historical FS'!F$9,3) -> 0.59 | G15: =ROUND('Consol. Historical FS'!G17/'Consol. Historical FS'!G$9,3) -> 0.595
B16: Depreciation and Amortisation Expense | C16: =ROUND('Consol. Historical FS'!C18/'Consol. Historical FS'!C$9,3) -> 0.168 | D16: =ROUND('Consol. Historical FS'!D18/'Consol. Historical FS'!D$9,3) -> 0.181 | E16: =ROUND('Consol. Historical FS'!E18/'Consol. Historical FS'!E$9,3) -> 0.164 | F16: =ROUND('Consol. Historical FS'!F18/'Consol. Historical FS'!F$9,3) -> 0.146 | G16: =ROUND('Consol. Historical FS'!G18/'Consol. Historical FS'!G$9,3) -> 0.144
B17: EBIT | C17: =ROUND('Consol. Historical FS'!C19/'Consol. Historical FS'!C$9,3) -> 0.525 | D17: =ROUND('Consol. Historical FS'!D19/'Consol. Historical FS'!D$9,3) -> 0.375 | E17: =ROUND('Consol. Historical FS'!E19/'Consol. Historical FS'!E$9,3) -> 0.361 | F17: =ROUND('Consol. Historical FS'!F19/'Consol. Historical FS'!F$9,3) -> 0.444 | G17: =ROUND('Consol. Historical FS'!G19/'Consol. Historical FS'!G$9,3) -> 0.452
B18: Finance Costs | C18: =ROUND('Consol. Historical FS'!C20/'Consol. Historical FS'!C$9,3) -> 0.18 | D18: =ROUND('Consol. Historical FS'!D20/'Consol. Historical FS'!D$9,3) -> 0.149 | E18: =ROUND('Consol. Historical FS'!E20/'Consol. Historical FS'!E$9,3) -> 0.113 | F18: =ROUND('Consol. Historical FS'!F20/'Consol. Historical FS'!F$9,3) -> 0.102 | G18: =ROUND('Consol. Historical FS'!G20/'Consol. Historical FS'!G$9,3) -> 0.083
B19: Other Income | C19: =ROUND('Consol. Historical FS'!C21/'Consol. Historical FS'!C$9,3) -> 0.157 | D19: =ROUND('Consol. Historical FS'!D21/'Consol. Historical FS'!D$9,3) -> 0.13 | E19: =ROUND('Consol. Historical FS'!E21/'Consol. Historical FS'!E$9,3) -> 0.075 | F19: =ROUND('Consol. Historical FS'!F21/'Consol. Historical FS'!F$9,3) -> 0.056 | G19: =ROUND('Consol. Historical FS'!G21/'Consol. Historical FS'!G$9,3) -> 0.063
B20: Profit before share of Profit / (Loss) of Associate / Joint Ventures | C20: =ROUND('Consol. Historical FS'!C22/'Consol. Historical FS'!C$9,3) -> 0.503 | D20: =ROUND('Consol. Historical FS'!D22/'Consol. Historical FS'!D$9,3) -> 0.357 | E20: =ROUND('Consol. Historical FS'!E22/'Consol. Historical FS'!E$9,3) -> 0.322 | F20: =ROUND('Consol. Historical FS'!F22/'Consol. Historical FS'!F$9,3) -> 0.398 | G20: =ROUND('Consol. Historical FS'!G22/'Consol. Historical FS'!G$9,3) -> 0.431
B21: Share of Profit / (Loss) from Associate /Joint Ventures (net of tax) | C21: =ROUND('Consol. Historical FS'!C23/'Consol. Historical FS'!C$9,3) -> -0.001 | D21: =ROUND('Consol. Historical FS'!D23/'Consol. Historical FS'!D$9,3) -> 0.001 | E21: =ROUND('Consol. Historical FS'!E23/'Consol. Historical FS'!E$9,3) -> 0.002 | F21: =ROUND('Consol. Historical FS'!F23/'Consol. Historical FS'!F$9,3) -> -0.006 | G21: =ROUND('Consol. Historical FS'!G23/'Consol. Historical FS'!G$9,3) -> 0.005
B22: Profit before Exceptional Items and Tax | C22: =ROUND('Consol. Historical FS'!C24/'Consol. Historical FS'!C$9,3) -> 0.501 | D22: =ROUND('Consol. Historical FS'!D24/'Consol. Historical FS'!D$9,3) -> 0.358 | E22: =ROUND('Consol. Historical FS'!E24/'Consol. Historical FS'!E$9,3) -> 0.324 | F22: =ROUND('Consol. Historical FS'!F24/'Consol. Historical FS'!F$9,3) -> 0.392 | G22: =ROUND('Consol. Historical FS'!G24/'Consol. Historical FS'!G$9,3) -> 0.436
... B32: Net Profit | C32: =ROUND('Consol. Historical FS'!C34/'Consol. Historical FS'!C$9,3) -> 0.402 | D32: =ROUND('Consol. Historical FS'!D34/'Consol. Historical FS'!D$9,3) -> 0.289 | E32: =ROUND('Consol. Historical FS'!E34/'Consol. Historical FS'!E$9,3) -> 0.259 | F32: =ROUND('Consol. Historical FS'!F34/'Consol. Historical FS'!F$9,3) -> 0.303 | G32: =ROUND('Consol. Historical FS'!G34/'Consol. Historical FS'!G$9,3) -> 0.363
B33: Net Profit attributable to:
B34: Owners of the company | C34: =ROUND('Consol. Historical FS'!C36/'Consol. Historical FS'!C$9,3) -> 0.398 | D34: =ROUND('Consol. Historical FS'!D36/'Consol. Historical FS'!D$9,3) -> 0.285 | E34: =ROUND('Consol. Historical FS'!E36/'Consol. Historical FS'!E$9,3) -> 0.255 | F34: =ROUND('Consol. Historical FS'!F36/'Consol. Historical FS'!F$9,3) -> 0.304 | G34: =ROUND('Consol. Historical FS'!G36/'Consol. Historical FS'!G$9,3) -> 0.364
B35: Non-Controlling Interest | C35: =ROUND('Consol. Historical FS'!C37/'Consol. Historical FS'!C$9,3) -> 0.004 | D35: =ROUND('Consol. Historical FS'!D37/'Consol. Historical FS'!D$9,3) -> 0.004 | E35: =ROUND('Consol. Historical FS'!E37/'Consol. Historical FS'!E$9,3) -> 0.004 | F35: =ROUND('Consol. Historical FS'!F37/'Consol. Historical FS'!F$9,3) -> 0 | G35: =ROUND('Consol. Historical FS'!G37/'Consol. Historical FS'!G$9,3) -> -0.001
A37: # | B37: Balance Sheet - as a % of Total Assets
B39: ASSETS
B40: Non-current Assets
B41: Property, Plant and Equipment | C41: =ROUND('Consol. Historical FS'!C43/'Consol. Historical FS'!C$73,3) -> 0.488 | D41: =ROUND('Consol. Historical FS'!D43/'Consol. Historical FS'!D$73,3) -> 0.416 | E41: =ROUND('Consol. Historical FS'!E43/'Consol. Historical FS'!E$73,3) -> 0.421 | F41: =ROUND('Consol. Historical FS'!F43/'Consol. Historical FS'!F$73,3) -> 0.436 | G41: =ROUND('Consol. Historical FS'!G43/'Consol. Historical FS'!G$73,3) -> 0.461
B42: Right of Use Assets | C42: =ROUND('Consol. Historical FS'!C44/'Consol. Historical FS'!C$73,3) -> 0.024 | D42: =ROUND('Consol. Historical FS'!D44/'Consol. Historical FS'!D$73,3) -> 0.028 | E42: =ROUND('Consol. Historical FS'!E44/'Consol. Historical FS'!E$73,3) -> 0.031 | F42: =ROUND('Consol. Historical FS'!F44/'Consol. Historical FS'!F$73,3) -> 0.032 | G42: =ROUND('Consol. Historical FS'!G44/'Consol. Historical FS'!G$73,3) -> 0.046
B43: Capital work-in-progress | C43: =ROUND('Consol. Historical FS'!C45/'Consol. Historical FS'!C$73,3) -> 0.049 | D43: =ROUND('Consol. Historical FS'!D45/'Consol. Historical FS'!D$73,3) -> 0.04 | E43: =ROUND('Consol. Historical FS'!E45/'Consol. Historical FS'!E$73,3) -> 0.059 | F43: =ROUND('Consol. Historical FS'!F45/'Consol. Historical FS'!F$73,3) -> 0.092 | G43: =ROUND('Consol. Historical FS'!G45/'Consol. Historical FS'!G$73,3) -> 0.086
B44: Investment Property | C44: =ROUND('Consol. Historical FS'!C46/'Consol. Historical FS'!C$73,3) -> 0 | D44: =ROUND('Consol. Historical FS'!D46/'Consol. Historical FS'!D$73,3) -> 0 | E44: =ROUND('Consol. Historical FS'!E46/'Consol. Historical FS'!E$73,3) -> 0.022 | F44: =ROUND('Consol. Historical FS'!F46/'Consol. Historical FS'!F$73,3) -> 0.011 | G44: =ROUND('Consol. Historical FS'!G46/'Consol. Historical FS'!G$73,3) -> 0.011
B45: Goodwill | C45: =ROUND('Consol. Historical FS'!C47/'Consol. Historical FS'!C$73,3) -> 0.054 | D45: =ROUND('Consol. Historical FS'!D47/'Consol. Historical FS'!D$73,3) -> 0.067 | E45: =ROUND('Consol. Historical FS'!E47/'Consol. Historical FS'!E$73,3) -> 0.061 | F45: =ROUND('Consol. Historical FS'!F47/'Consol. Historical FS'!F$73,3) -> 0.058 | G45: =ROUND('Consol. Historical FS'!G47/'Consol. Historical FS'!G$73,3) -> 0.052
B46: Other Intangible Assets | C46: =ROUND('Consol. Historical FS'!C48/'Consol. Historical FS'!C$73,3) -> 0.073 | D46: =ROUND('Consol. Historical FS'!D48/'Consol. Historical FS'!D$73,3) -> 0.116 | E46: =ROUND('Consol. Historical FS'!E48/'Consol. Historical FS'!E$73,3) -> 0.1 | F46: =ROUND('Consol. Historical FS'!F48/'Consol. Historical FS'!F$73,3) -> 0.095 | G46: =ROUND('Consol. Historical FS'!G48/'Consol. Historical FS'!G$73,3) -> 0.092
B47: Intangible Assets under Development | C47: =ROUND('Consol. Historical FS'!C49/'Consol. Historical FS'!C$73,3) -> 0 | D47: =ROUND('Consol. Historical FS'!D49/'Consol. Historical FS'!D$73,3) -> 0 | E47: =ROUND('Consol. Historical FS'!E49/'Consol. Historical FS'!E$73,3) -> 0 | F47: =ROUND('Consol. Historical FS'!F49/'Consol. Historical FS'!F$73,3) -> 0 | G47: =ROUND('Consol. Historical FS'!G49/'Consol. Historical FS'!G$73,3) -> 0.001
B48: Investments accounted for using the equity method | C48: =ROUND('Consol. Historical FS'!C50/'Consol. Historical FS'!C$73,3) -> 0.009 | D48: =ROUND('Consol. Historical FS'!D50/'Consol. Historical FS'!D$73,3) -> 0.012 | E48: =ROUND('Consol. Historical FS'!E50/'Consol. Historical FS'!E$73,3) -> 0.022 | F48: =ROUND('Consol. Historical FS'!F50/'Consol. Historical FS'!F$73,3) -> 0.023 | G48: =ROUND('Consol. Historical FS'!G50/'Consol. Historical FS'!G$73,3) -> 0.023
B49: Financial assets | C49: =ROUND('Consol. Historical FS'!C51/'Consol. Historical FS'!C$73,3) -> 0 | D49: =ROUND('Consol. Historical FS'!D51/'Consol. Historical FS'!D$73,3) -> 0 | E49: =ROUND('Consol. Historical FS'!E51/'Consol. Historical FS'!E$73,3) -> 0 | F49: =ROUND('Consol. Historical FS'!F51/'Consol. Historical FS'!F$73,3) -> 0 | G49: =ROUND('Consol. Historical FS'!G51/'Consol. Historical FS'!G$73,3) -> 0
B50: a) Other Investments | C50: =ROUND('Consol. Historical FS'!C52/'Consol. Historical FS'!C$73,3) -> 0.006 | D50: =ROUND('Consol. Historical FS'!D52/'Consol. Historical FS'!D$73,3) -> 0.019 | E50: =ROUND('Consol. Historical FS'!E52/'Consol. Historical FS'!E$73,3) -> 0.009 | F50: =ROUND('Consol. Historical FS'!F52/'Consol. Historical FS'!F$73,3) -> 0.008 | G50: =ROUND('Consol. Historical FS'!G52/'Consol. Historical FS'!G$73,3) -> 0.006
B51: b) Other Financial Assets | C51: =ROUND('Consol. Historical FS'!C53/'Consol. Historical FS'!C$73,3) -> 0.081 | D51: =ROUND('Consol. Historical FS'!D53/'Consol. Historical FS'!D$73,3) -> 0.083 | E51: =ROUND('Consol. Historical FS'!E53/'Consol. Historical FS'!E$73,3) -> 0.067 | F51: =ROUND('Consol. Historical FS'!F53/'Consol. Historical FS'!F$73,3) -> 0.04 | G51: =ROUND('Consol. Historical FS'!G53/'Consol. Historical FS'!G$73,3) -> 0.042
B52: Deferred Tax Assets (Net) | C52: =ROUND('Consol. Historical FS'!C54/'Consol. Historical FS'!C$73,3) -> 0.012 | D52: =ROUND('Consol. Historical FS'!D54/'Consol. Historical FS'!D$73,3) -> 0.014 | E52: =ROUND('Consol. Historical FS'!E54/'Consol. Historical FS'!E$73,3) -> 0.019 | F52: =ROUND('Consol. Historical FS'!F54/'Consol. Historical FS'!F$73,3) -> 0.016 | G52: =ROUND('Consol. Historical FS'!G54/'Consol. Historical FS'!G$73,3) -> 0.014
... B55: Total Non-current Assets | C55: =ROUND('Consol. Historical FS'!C57/'Consol. Historical FS'!C$73,3) -> 0.83 | D55: =ROUND('Consol. Historical FS'!D57/'Consol. Historical FS'!D$73,3) -> 0.819 | E55: =ROUND('Consol. Historical FS'!E57/'Consol. Historical FS'!E$73,3) -> 0.848 | F55: =ROUND('Consol. Historical FS'!F57/'Consol. Historical FS'!F$73,3) -> 0.853 | G55: =ROUND('Consol. Historical FS'!G57/'Consol. Historical FS'!G$73,3) -> 0.86
B57: Current assets
...

Sheet 2Q26 Performance
C3: 2Q'26 Financial Performance (Consolidated):
C5: ₹'cr unless stated otherwise | D5: Q2 FY26 | E5: Q1 FY26 | F5: Q-o-Q | G5: Q2 FY25 | H5: Y-o-Y | I5: H1 FY26 | J5: H1 FY25 | K5: Y-o-Y
C6: Revenue from Operations | D6: 9167.46 | E6: 9126.14 | F6: =D6/E6-1 -> 0.0045276535 | G6: 7067.02 | H6: =D6/G6-1 -> 0.29721721 | I6: =D6+E6 -> 18293.6 | J6: 14023.34 | K6: =I6/J6-1 -> 0.30451091
C7: Gross Profit | D7: =D6-2496.35 -> 6671.11 | E7: =E6-2526.29 -> 6599.85 | F7: =D7/E7-1 -> 0.010797215 | G7: =G6-1762.82 -> 5304.2 | H7: =D7/G7-1 -> 0.25770333 | I7: =I6-5022.64 -> 13270.96 | J7: =J6-3629.39 -> 10393.95 | K7: =I7/J7-1 -> 0.2767966
C8: Gross Profit Margin | D8: =D7/D$6 -> 0.72769448 | E8: =E7/E$6 -> 0.72318088 | F8: =D8-E8 -> 0.0045135911 | G8: =G7/G$6 -> 0.75055681 | H8: =D8-G8 -> -0.022862336 | I8: =I7/I$6 -> 0.72544278 | J8: =J7/J$6 -> 0.74118933 | K8: =I8-J8 -> -0.015746554
C9: EBITDA | D9: =D7-585.51-535.33 -> 5550.27 | E9: =E7-569.21-535.31 -> 5495.33 | F9: =D9/E9-1 -> 0.0099975798 | G9: =G7-506.06-429.27 -> 4368.87 | H9: =D9/G9-1 -> 0.27041317 | I9: =I7-1154.72-1070.64 -> 11045.6 | J9: =J7-975.33-805.27 -> 8613.35 | K9: =I9/J9-1 -> 0.28238142
C10: EBITDA Margin | D10: =D9/D$6 -> 0.6054316 | E10: =E9/E$6 -> 0.60215272 | F10: =D10-E10 -> 0.0032788853 | G10: =G9/G$6 -> 0.61820541 | H10: =D10-G10 -> -0.012773808 | I10: =I9/I$6 -> 0.60379586 | J10: =J9/J$6 -> 0.6142153 | K10: =I10-J10 -> -0.010419438
C11: PAT | D11: 3120.2 | E11: 3310.6 | F11: =D11/E11-1 -> -0.057512233 | G11: 2412.54 | H11: =D11/G11-1 -> 0.29332571 | I11: 6430.8 | J11: 5519.77 | K11: =I11/J11-1 -> 0.16504854
C12: PAT Margin | D12: =D11/D$6 -> 0.340356 | E12: =E11/E$6 -> 0.36276016 | F12: =D12-E12 -> -0.022404161 | G12: =G11/G$6 -> 0.3413801 | H12: =D12-G12 -> -0.0010241025 | I12: =I11/I$6 -> 0.35153278 | J12: =J11/J$6 -> 0.39361308 | K12: =I12-J12 -> -0.0420803
C13: Owners of the Company | D13: 3109.05 | E13: 3314.59 | F13: =D13/E13-1 -> -0.062010686 | G13: 2445 | H13: =D13/G13-1 -> 0.27159509 | I13: 6423.64 | J13: 5557.83 | K13: =I13/J13-1 -> 0.15578202
C14: Non-controlling interests | D14: =D11-D13 -> 11.15 | E14: =E11-E13 -> -3.99 | F14: =D14/E14-1 -> -3.7944862 | G14: =G11-G13 -> -32.46 | H14: =D14/G14-1 -> -1.3434997 | I14: =I11-I13 -> 7.16 | J14: =J11-J13 -> -38.06 | K14: =I14/J14-1 -> -1.188124
C15: EPS | D15: 14.39 | E15: 15.34 | F15: =D15/E15-1 -> -0.061929596 | G15: 11.32 | H15: =D15/G15-1 -> 0.27120141 | I15: 29.74 | J15: 25.73 | K15: =I15/J15-1 -> 0.1558492
C17: Segmental Data
C18: Revenue from Operations
C19: Ports and SEZ Activities | D19: 8054.13 | E19: 7652.89 | F19: =D19/E19-1 -> 0.052429866 | G19: 6421.03 | H19: =D19/G19-1 -> 0.25433614 | I19: =D19+E19 -> 15707.02 | J19: 13360.37 | K19: =I19/J19-1 -> 0.17564259
C20: Others | D20: 1196.35 | E20: 1515.71 | F20: =D20/E20-1 -> -0.21069994 | G20: 678.88 | H20: =D20/G20-1 -> 0.76224075 | I20: =D20+E20 -> 2712.06 | J20: 1334.55 | K20: =I20/J20-1 -> 1.0321906
C21: Less: Inter-Segment Revenue | D21: -83.02 | E21: -42.46 | F21: =D21/E21-1 -> 0.955252 | G21: -32.89 | H21: =D21/G21-1 -> 1.5241715 | I21: =D21+E21 -> -125.48 | J21: -68.31 | K21: =I21/J21-1 -> 0.83691992
C22: Total Revenue | D22: =SUM(D19:D21) -> 9167.46 | E22: =SUM(E19:E21) -> 9126.14 | F22: =D22/E22-1 -> 0.0045276535 | G22: =SUM(G19:G21) -> 7067.02 | H22: =D22/G22-1 -> 0.29721721 | I22: =D22+E22 -> 18293.6 | J22: =SUM(J19:J21) -> 14626.61 | K22: =I22/J22-1 -> 0.25070676
C24: EBITDA Margin
C25: Domestic Ports | D25: 0.738 | E25: 0.746 | F25: =D25-E25 -> -0.008 | G25: 0.729 | H25: =D25-G25 -> 0.009 | I25: 0.742 | J25: 0.727 | K25: =I25-J25 -> 0.015
C26: International Ports | D26: 0.242 | E26: 0.211 | F26: =D26-E26 -> 0.031 | G26: 0.145 | H26: =D26-G26 -> 0.097 | I26: 0.227 | J26: 0.136 | K26: =I26-J26 -> 0.091
C27: Logistics | D27: 0.209 | E27: 0.181 | F27: =D27-E27 -> 0.028 | G27: 0.265 | H27: =D27-G27 -> -0.056 | I27: 0.194 | J27: 0.259 | K27: =I27-J27 -> -0.065
C28: Marine | D28: 0.527 | E28: 0.55 | F28: =D28-E28 -> -0.023 | G28: 0.463 | H28: =D28-G28 -> 0.064 | I28: 0.537 | J28: 0.431 | K28: =I28-J28 -> 0.106
C29: Port development & SEZ | D29: 1 | E29: 0.593 | F29: =D29-E29 -> 0.407 | G29: 1 | H29: =D29-G29 -> 0 | I29: 0.655 | J29: 1 | K29: =I29-J29 -> -0.345

Sheet Projected Financials
A13: Projected Financials -->>

Sheet 3 Model Projected FS
I1: =[2]Scenarios!L1 -> Currently Running: Base Case Scenario
B2: CONSOLIDATED - PROJECTED FINANCIAL STATEMENTS
B3: ₹'cr, unless otherwise stated | C3: ='Consol. Historical FS'!C3 -> FY21A | D3: ='Consol. Historical FS'!D3 -> FY22A | E3: ='Consol. Historical FS'!E3 -> FY23A | F3: ='Consol. Historical FS'!F3 -> FY24A | G3: ='Consol. Historical FS'!G3 -> FY25A | H3: FY26E | I3: FY27E
A5: # | B5: Profit & Loss Statement
B7: Revenue from Operations | C7: ='Consol. Historical FS'!C7 -> 12549.6 | D7: ='Consol. Historical FS'!D7 -> 17118.79 | E7: ='Consol. Historical FS'!E7 -> 20851.91 | F7: ='Consol. Historical FS'!F7 -> 26710.56 | G7: ='Consol. Historical FS'!G7 -> 30475.33
B8: Other Operating Revenues | C8: ='Consol. Historical FS'!C8 -> 0 | D8: ='Consol. Historical FS'!D8 -> 0 | E8: ='Consol. Historical FS'!E8 -> 0 | F8: ='Consol. Historical FS'!F8 -> 0 | G8: ='Consol. Historical FS'!G8 -> 0
B9: Total Revenue | C9: =ROUND(SUM(C7:C8),2) -> 12549.6 | D9: =SUM(D7:D8) -> 17118.79 | E9: =SUM(E7:E8) -> 20851.91 | F9: =SUM(F7:F8) -> 26710.56 | G9: =SUM(G7:G8) -> 30475.33 | H9: =Scenarios!K11 -> 37803.28 | I9: =Scenarios!L11 -> 46945.27
B10: Revenue Growth YoY | D10: =ROUND(D9/C9-1,3) -> 0.364 | E10: =ROUND(E9/D9-1,3) -> 0.218 | F10: =ROUND(F9/E9-1,3) -> 0.281 | G10: =ROUND(G9/F9-1,3) -> 0.141 | H10: =ROUND(H9/G9-1,3) -> 0.24 | I10: =ROUND(I9/H9-1,3) -> 0.242 | T10: ='3 Model Projected FS'!G84/'3 Model Projected FS'!G113*#REF!+('3 Model Projected FS'!G96+'3 Model Projected FS'!G111)/'3 Model Projected FS'!G113 -> #REF!
B13: Operating Expenses | C13: ='Consol. Historical FS'!C10 -> 3259.49 | D13: ='Consol. Historical FS'!D10 -> 4865.11 | E13: ='Consol. Historical FS'!E10 -> 5654.56 | F13: ='Consol. Historical FS'!F10 -> 7116.34 | G13: ='Consol. Historical FS'!G10 -> 8069.75 | H13: =Scenarios!K156 -> 10017.87 | I13: =Scenarios!L156 -> 12299.66
B14: Gross Profit | C14: =ROUND(C9-SUM(C13:C13),2) -> 9290.11 | D14: =ROUND(D9-SUM(D13:D13),2) -> 12253.68 | E14: =ROUND(E9-SUM(E13:E13),2) -> 15197.35 | F14: =ROUND(F9-SUM(F13:F13),2) -> 19594.22 | G14: =ROUND(G9-SUM(G13:G13),2) -> 22405.58 | H14: =ROUND(H9-SUM(H13:H13),2) -> 27785.41 | I14: =ROUND(I9-SUM(I13:I13),2) -> 34645.61
B15: Gross Profit Margin | C15: =ROUND(C14/C9,3) -> 0.74 | D15: =ROUND(D14/D9,3) -> 0.716 | E15: =ROUND(E14/E9,3) -> 0.729 | F15: =ROUND(F14/F9,3) -> 0.734 | G15: =ROUND(G14/G9,3) -> 0.735 | H15: =ROUND(H14/H9,3) -> 0.735 | I15: =ROUND(I14/I9,3) -> 0.738
B16: Employee Benefits Expense | C16: ='Consol. Historical FS'!C14 -> 615.05 | D16: ='Consol. Historical FS'!D14 -> 779.43 | E16: ='Consol. Historical FS'!E14 -> 1178.17 | F16: ='Consol. Historical FS'!F14 -> 1896.4 | G16: ='Consol. Historical FS'!G14 -> 2008.66 | H16: =Scenarios!K182 -> 2381.61 | I16: =Scenarios!L182 -> 3051.44
B17: Loss on fair valuation of Compulsorily Convertible Preference Shares | C17: ='Consol. Historical FS'!C15 -> 0 | D17: ='Consol. Historical FS'!D15 -> 0 | E17: ='Consol. Historical FS'!E15 -> 0 | F17: ='Consol. Historical FS'!F15 -> 0 | G17: ='Consol. Historical FS'!G15 -> 0 | H17: =Scenarios!K190 -> 0 | I17: =Scenarios!L190 -> 0
B18: Other Expenses | C18: ='Consol. Historical FS'!C16 -> -23.62 | D18: ='Consol. Historical FS'!D16 -> 1949.81 | E18: ='Consol. Historical FS'!E16 -> 3072.05 | F18: ='Consol. Historical FS'!F16 -> 1946.72 | G18: ='Consol. Historical FS'!G16 -> 2256.4 | H18: =Scenarios!K198 -> 2721.84 | I18: =Scenarios!L198 -> 3380.06
B19: EBITDA | C19: =ROUND(C14-SUM(C16:C18),2) -> 8698.68 | D19: =ROUND(D14-SUM(D16:D18),2) -> 9524.44 | E19: =ROUND(E14-SUM(E16:E18),2) -> 10947.13 | F19: =ROUND(F14-SUM(F16:F18),2) -> 15751.1 | G19: =ROUND(G14-SUM(G16:G18),2) -> 18140.52 | H19: =ROUND(H14-SUM(H16:H18),2) -> 22681.96 | I19: =ROUND(I14-SUM(I16:I18),2) -> 28214.11
B20: EBITDA Margin | C20: =ROUND(C19/C9,3) -> 0.693 | D20: =ROUND(D19/D9,3) -> 0.556 | E20: =ROUND(E19/E9,3) -> 0.525 | F20: =ROUND(F19/F9,3) -> 0.59 | G20: =ROUND(G19/G9,3) -> 0.595 | H20: =ROUND(H19/H9,3) -> 0.6 | I20: =ROUND(I19/I9,3) -> 0.601
B21: Depreciation and Amortisation Expense | C21: ='Consol. Historical FS'!C18 -> 2107.34 | D21: ='Consol. Historical FS'!D18 -> 3099.3 | E21: ='Consol. Historical FS'!E18 -> 3423.24 | F21: ='Consol. Historical FS'!F18 -> 3888.46 | G21: ='Consol. Historical FS'!G18 -> 4378.93 | H21: =Scenarios!K427 -> 5229.0037 | I21: =Scenarios!L427 -> 5925.2319
B22: EBIT | C22: =ROUND(C19-C21,2) -> 6591.34 | D22: =ROUND(D19-D21,2) -> 6425.14 | E22: =ROUND(E19-E21,2) -> 7523.89 | F22: =ROUND(F19-F21,2) -> 11862.64 | G22: =ROUND(G19-G21,2) -> 13761.59 | H22: =ROUND(H19-H21,2) -> 17452.96 | I22: =ROUND(I19-I21,2) -> 22288.88
B23: Finance Costs | C23: ='Consol. Historical FS'!C20 -> 2255.29 | D23: ='Consol. Historical FS'!D20 -> 2543.92 | E23: ='Consol. Historical FS'!E20 -> 2362.64 | F23: ='Consol. Historical FS'!F20 -> 2732.94 | G23: ='Consol. Historical FS'!G20 -> 2531.82 | H23: =Scenarios!K418 -> 3063.5022 | I23: =Scenarios!L418 -> 3706.8377
B24: Other Income | C24: ='Consol. Historical FS'!C21 -> 1970.23 | D24: ='Consol. Historical FS'!D21 -> 2223.72 | E24: ='Consol. Historical FS'!E21 -> 1553.48 | F24: ='Consol. Historical FS'!F21 -> 1499.42 | G24: ='Consol. Historical FS'!G21 -> 1907.75 | H24: =Scenarios!K212 -> 2268.2 | I24: =Scenarios!L212 -> 2910.61
B25: Profit before share of Profit / (Loss) of Associate / Joint Ventures | C25: =ROUND(C22-C23+C24,2) -> 6306.28 | D25: =ROUND(D22-D23+D24,2) -> 6104.94 | E25: =ROUND(E22-E23+E24,2) -> 6714.73 | F25: =ROUND(F22-F23+F24,2) -> 10629.12 | G25: =ROUND(G22-G23+G24,2) -> 13137.52 | H25: =ROUND(H22-H23+H24,2) -> 16657.66 | I25: =ROUND(I22-I23+I24,2) -> 21492.65
B26: Share of Profit / (Loss) from Associate /Joint Ventures (net of tax) | C26: ='Consol. Historical FS'!C23 -> -14.27 | D26: ='Consol. Historical FS'!D23 -> 17.39 | E26: ='Consol. Historical FS'!E23 -> 47.78 | F26: ='Consol. Historical FS'!F23 -> -161.69 | G26: ='Consol. Historical FS'!G23 -> 141.56 | H26: =Scenarios!K220 -> 0 | I26: =Scenarios!L220 -> 0
B27: Profit before Exceptional Items and Tax | C27: =ROUND(SUM(C25:C26),2) -> 6292.01 | D27: =ROUND(SUM(D25:D26),2) -> 6122.33 | E27: =ROUND(SUM(E25:E26),2) -> 6762.51 | F27: =ROUND(SUM(F25:F26),2) -> 10467.43 | G27: =ROUND(SUM(G25:G26),2) -> 13279.08 | H27: =ROUND(SUM(H25:H26),2) -> 16657.66 | I27: =ROUND(SUM(I25:I26),2) -> 21492.65
B28: Exceptional Items | C28: ='Consol. Historical FS'!C25 -> 0 | D28: ='Consol. Historical FS'!D25 -> -405.19 | E28: ='Consol. Historical FS'!E25 -> -1273.38 | F28: ='Consol. Historical FS'!F25 -> -373.7 | G28: ='Consol. Historical FS'!G25 -> -249.46 | H28: =Scenarios!K228 -> -37.8 | I28: =Scenarios!L228 -> -46.95
B29: Profit before Tax | C29: =ROUND(SUM(C27:C28),2) -> 6292.01 | D29: =ROUND(SUM(D27:D28),2) -> 5717.14 | E29: =ROUND(SUM(E27:E28),2) -> 5489.13 | F29: =ROUND(SUM(F27:F28),2) -> 10093.73 | G29: =ROUND(SUM(G27:G28),2) -> 13029.62 | H29: =ROUND(SUM(H27:H28),2) -> 16619.86 | I29: =ROUND(SUM(I27:I28),2) -> 21445.7
B30: Tax | C30: ='Consol. Historical FS'!C27+'Consol. Historical FS'!C28+'Consol. Historical FS'!C29 -> 1243.27 | D30: ='Consol. Historical FS'!D27+'Consol. Historical FS'!D28+'Consol. Historical FS'!D29 -> 763.96 | E30: ='Consol. Historical FS'!E27+'Consol. Historical FS'!E28+'Consol. Historical FS'!E29 -> 96.38 | F30: ='Consol. Historical FS'!F27+'Consol. Historical FS'!F28+'Consol. Historical FS'!F29 -> 1989.74 | G30: ='Consol. Historical FS'!G27+'Consol. Historical FS'!G28+'Consol. Historical FS'!G29 -> 1968.36 | H30: =ROUND(H29*Scenarios!K252,2) -> 2659.18 | I30: =ROUND(I29*Scenarios!L252,2) -> 3431.31
B31: Tax Burden | C31: =ROUND(C30/C29,3) -> 0.198 | D31: =ROUND(D30/D29,3) -> 0.134 | E31: =ROUND(E30/E29,3) -> 0.018 | F31: =ROUND(F30/F29,3) -> 0.197 | G31: =ROUND(G30/G29,3) -> 0.151 | H31: =ROUND(H30/H29,3) -> 0.16 | I31: =ROUND(I30/I29,3) -> 0.16
B32: Net profit from continuing operations | C32: =ROUND(C29-C30,2) -> 5048.74 | D32: =ROUND(D29-D30,2) -> 4953.18 | E32: =ROUND(E29-E30,2) -> 5392.75 | F32: =ROUND(F29-F30,2) -> 8103.99 | G32: =ROUND(G29-G30,2) -> 11061.26 | H32: =ROUND(H29-H30,2) -> 13960.68 | I32: =ROUND(I29-I30,2) -> 18014.39
B33: Profit before tax from discontinued operations | C33: ='Consol. Historical FS'!C31 -> 0 | D33: ='Consol. Historical FS'!D31 -> 0 | E33: ='Consol. Historical FS'!E31 -> 0 | F33: ='Consol. Historical FS'!F31 -> 0 | G33: ='Consol. Historical FS'!G31 -> 0 | H33: =Scenarios!K236 -> 0 | I33: =Scenarios!L236 -> 0
B34: Tax income / (expense) of discontinued operations | C34: ='Consol. Historical FS'!C32 -> 0 | D34: ='Consol. Historical FS'!D32 -> 0 | E34: ='Consol. Historical FS'!E32 -> 0 | F34: ='Consol. Historical FS'!F32 -> 0 | G34: ='Consol. Historical FS'!G32 -> 0 | H34: =Scenarios!K244 -> 0 | I34: =Scenarios!L244 -> 0
B35: Net profit from discontinuing operations | C35: =ROUND(SUM(C33:C34),2) -> 0 | D35: =ROUND(SUM(D33:D34),2) -> 0 | E35: =ROUND(SUM(E33:E34),2) -> 0 | F35: =ROUND(SUM(F33:F34),2) -> 0 | G35: =ROUND(SUM(G33:G34),2) -> 0 | H35: =ROUND(SUM(H33:H34),2) -> 0 | I35: =ROUND(SUM(I33:I34),2) -> 0
B36: Net Profit | C36: =ROUND(SUM(C32,C35),2) -> 5048.74 | D36: =ROUND(SUM(D32,D35),2) -> 4953.18 | E36: =ROUND(SUM(E32,E35),2) -> 5392.75 | F36: =ROUND(SUM(F32,F35),2) -> 8103.99 | G36: =ROUND(SUM(G32,G35),2) -> 11061.26 | H36: =ROUND(SUM(H32,H35),2) -> 13960.68 | I36: =ROUND(SUM(I32,I35),2) -> 18014.39
B37: Net Profit Margin | C37: =ROUND(C36/C9,3) -> 0.402 | D37: =ROUND(D36/D9,3) -> 0.289 | E37: =ROUND(E36/E9,3) -> 0.259 | F37: =ROUND(F36/F9,3) -> 0.303 | G37: =ROUND(G36/G9,3) -> 0.363 | H37: =ROUND(H36/H9,3) -> 0.369 | I37: =ROUND(I36/I9,3) -> 0.384
B38: Net Profit attributable to:
B39: Owners of the company | C39: ='Consol. Historical FS'!C36 -> 4994.3 | D39: ='Consol. Historical FS'!D36 -> 4886.03 | E39: ='Consol. Historical FS'!E36 -> 5310.18 | F39: ='Consol. Historical FS'!F36 -> 8110.64 | G39: ='Consol. Historical FS'!G36 -> 11092.31 | H39: =ROUND(H36*Scenarios!K256,2) -> 13999.87 | I39: =ROUND(I36*Scenarios!L256,2) -> 18064.96
B40: Non-Controlling Interest | C40: ='Consol. Historical FS'!C37 -> 54.44 | D40: ='Consol. Historical FS'!D37 -> 67.15 | E40: ='Consol. Historical FS'!E37 -> 82.57 | F40: ='Consol. Historical FS'!F37 -> -6.65 | G40: ='Consol. Historical FS'!G37 -> -31.05 | H40: =ROUND(H36*Scenarios!K259,2) -> -39.19 | I40: =ROUND(I36*Scenarios!L259,2) -> -50.57
A42: # | B42: Balance Sheet
B44: ASSETS
B45: Non-current Assets
B46: Property, Plant and Equipment | C46: ='Consol. Historical FS'!C43 -> 36791.51 | D46: ='Consol. Historical FS'!D43 -> 41488.7 | E46: ='Consol. Historical FS'!E43 -> 48414 | F46: ='Consol. Historical FS'!F43 -> 51803.83 | G46: ='Consol. Historical FS'!G43 -> 62394.43 | H46: =G46/Scenarios!J$426*Scenarios!K$426 -> 74595.961 | I46: =H46/Scenarios!K$426*Scenarios!L$426 -> 84528.219
...

Sheet Financial Ratios
G1: =[2]Scenarios!L1 -> Currently Running: Base Case Scenario
B2: FINANCIAL RATIOS
C3: ='3 Model Projected FS'!E3 -> FY23A | D3: ='3 Model Projected FS'!F3 -> FY24A | E3: ='3 Model Projected FS'!G3 -> FY25A | F3: FY26E | G3: FY27E
B4: Key Ratios
B5: Revenue Growth | C5: =ROUND('3 Model Projected FS'!E9/'3 Model Projected FS'!D9-1,3) -> 0.218 | D5: =ROUND('3 Model Projected FS'!F9/'3 Model Projected FS'!E9-1,3) -> 0.281 | E5: =ROUND('3 Model Projected FS'!G9/'3 Model Projected FS'!F9-1,3) -> 0.141 | F5: =ROUND('3 Model Projected FS'!H9/'3 Model Projected FS'!G9-1,3) -> 0.24 | G5: =ROUND('3 Model Projected FS'!I9/'3 Model Projected FS'!H9-1,3) -> 0.242
B6: Gross Profit Growth | C6: =ROUND('3 Model Projected FS'!E14/'3 Model Projected FS'!D14-1,3) -> 0.24 | D6: =ROUND('3 Model Projected FS'!F14/'3 Model Projected FS'!E14-1,3) -> 0.289 | E6: =ROUND('3 Model Projected FS'!G14/'3 Model Projected FS'!F14-1,3) -> 0.143 | F6: =ROUND('3 Model Projected FS'!H14/'3 Model Projected FS'!G14-1,3) -> 0.24 | G6: =ROUND('3 Model Projected FS'!I14/'3 Model Projected FS'!H14-1,3) -> 0.247
B7: EBITDA Growth | C7: =ROUND('3 Model Projected FS'!E19/'3 Model Projected FS'!D19-1,3) -> 0.149 | D7: =ROUND('3 Model Projected FS'!F19/'3 Model Projected FS'!E19-1,3) -> 0.439 | E7: =ROUND('3 Model Projected FS'!G19/'3 Model Projected FS'!F19-1,3) -> 0.152 | F7: =ROUND('3 Model Projected FS'!H19/'3 Model Projected FS'!G19-1,3) -> 0.25 | G7: =ROUND('3 Model Projected FS'!I19/'3 Model Projected FS'!H19-1,3) -> 0.244
B8: Net Profit Growth | C8: =ROUND('3 Model Projected FS'!E36/'3 Model Projected FS'!D36-1,3) -> 0.089 | D8: =ROUND('3 Model Projected FS'!F36/'3 Model Projected FS'!E36-1,3) -> 0.503 | E8: =ROUND('3 Model Projected FS'!G36/'3 Model Projected FS'!F36-1,3) -> 0.365 | F8: =ROUND('3 Model Projected FS'!H36/'3 Model Projected FS'!G36-1,3) -> 0.262 | G8: =ROUND('3 Model Projected FS'!I36/'3 Model Projected FS'!H36-1,3) -> 0.29
B9: RoCE | C9: =Graphs!D23 -> 0.082 | D9: =Graphs!E23 -> 0.12 | E9: =Graphs!F23 -> 0.13 | F9: =Graphs!G23 -> 0.155 | G9: =Graphs!H23 -> 0.177
B10: RoE | C10: =Graphs!D24 -> 0.121 | D10: =Graphs!E24 -> 0.165 | E10: =Graphs!F24 -> 0.192 | F10: =Graphs!G24 -> 0.229 | G10: =Graphs!H24 -> 0.266
B11: Dividend Payout Ratio | C11: =ROUND(Scenarios!H393/'3 Model Projected FS'!E39,3) -> 0.203 | D11: =ROUND(Scenarios!I393/'3 Model Projected FS'!F39,3) -> 0.16 | E11: =ROUND(Scenarios!J393/'3 Model Projected FS'!G39,3) -> 0.14 | F11: =ROUND(Scenarios!K393/'3 Model Projected FS'!H39,3) -> 0.15 | G11: =ROUND(Scenarios!L393/'3 Model Projected FS'!I39,3) -> 0.155
B12: EPS (₹) | C12: =Scenarios!H395 -> 24.58 | D12: =Scenarios!I395 -> 37.55 | E12: =Scenarios!J395 -> 51.35 | F12: =Scenarios!K395 -> 64.81 | G12: =Scenarios!L395 -> 83.63
B13: Gross Fixed Asset Turnover (x) | C13: =Graphs!D10 -> 0.5 | D13: =Graphs!E10 -> 0.3 | E13: =Graphs!F10 -> 0.3 | F13: =Graphs!G10 -> 0.4 | G13: =Graphs!H10 -> 0.4
B14: Net Working Capital Days | C14: =C15+C16-C17 -> -22 | D14: =D15+D16-D17 -> -25 | E14: =E15+E16-E17 -> -34 | F14: =F15+F16-F17 -> -30 | G14: =G15+G16-G17 -> -34
B15: Debtor Days | C15: =Graphs!D17 -> 48 | D15: =Graphs!E17 -> 47 | E15: =Graphs!F17 -> 49 | F15: =Graphs!G17 -> 48 | G15: =Graphs!H17 -> 47
B16: Inventory Days | C16: =Graphs!D21 -> 27 | D16: =Graphs!E21 -> 23 | E16: =Graphs!F21 -> 22 | F16: =Graphs!G21 -> 23 | G16: =Graphs!H21 -> 23
B17: Payable Days | C17: =Graphs!D19 -> 97 | D17: =Graphs!E19 -> 95 | E17: =Graphs!F19 -> 105 | F17: =Graphs!G19 -> 101 | G17: =Graphs!H19 -> 104
B18: Net Debt to Equity (x) | C18: =ROUND((SUM('3 Model Projected FS'!E88,'3 Model Projected FS'!E100)-SUM('3 Model Projected FS'!E67:E68))/'3 Model Projected FS'!E82,1) -> 1 | D18: =ROUND((SUM('3 Model Projected FS'!F88,'3 Model Projected FS'!F100)-SUM('3 Model Projected FS'!F67:F68))/'3 Model Projected FS'!F82,1) -> 0.7 | E18: =ROUND((SUM('3 Model Projected FS'!G88,'3 Model Projected FS'!G100)-SUM('3 Model Projected FS'!G67:G68))/'3 Model Projected FS'!G82,1) -> 0.6 | F18: =ROUND((SUM('3 Model Projected FS'!H88,'3 Model Projected FS'!H100)-SUM('3 Model Projected FS'!H67:H68))/'3 Model Projected FS'!H82,1) -> 0.6 | G18: =ROUND((SUM('3 Model Projected FS'!I88,'3 Model Projected FS'!I100)-SUM('3 Model Projected FS'!I67:I68))/'3 Model Projected FS'!I82,1) -> 0.5
B19: Interest Coverage (x) | C19: =ROUND('3 Model Projected FS'!E22/'3 Model Projected FS'!E23,1) -> 3.2 | D19: =ROUND('3 Model Projected FS'!F22/'3 Model Projected FS'!F23,1) -> 4.3 | E19: =ROUND('3 Model Projected FS'!G22/'3 Model Projected FS'!G23,1) -> 5.4 | F19: =ROUND('3 Model Projected FS'!H22/'3 Model Projected FS'!H23,1) -> 5.7 | G19: =ROUND('3 Model Projected FS'!I22/'3 Model Projected FS'!I23,1) -> 6
B20: CFO / EBITDA | C20: =ROUND('3 Model Projected FS'!E156/'3 Model Projected FS'!E19,3) -> 1.09 | D20: =ROUND('3 Model Projected FS'!F156/'3 Model Projected FS'!F19,3) -> 0.953 | E20: =ROUND('3 Model Projected FS'!G156/'3 Model Projected FS'!G19,3) -> 0.95 | F20: =ROUND('3 Model Projected FS'!H156/'3 Model Projected FS'!H19,3) -> 0.926 | G20: =ROUND('3 Model Projected FS'!I156/'3 Model Projected FS'!I19,3) -> 0.937

Sheet Summary_3 Model Projected FS
I1: =[2]Scenarios!L1 -> Currently Running: Base Case Scenario
B2: CONSOLIDATED - SUMMARY PROJECTED FINANCIAL STATEMENTS
B3: ₹'cr, unless otherwise stated | C3: =[2]Consol!C3 -> #VALUE! | D3: =[2]Consol!D3 -> #VALUE! | E3: =[2]Consol!E3 -> #VALUE! | F3: FY24A | G3: FY25A | H3: FY26E | I3: FY27E
A5: # | B5: Profit & Loss Statement
B7: Total Revenue | C7: ='3 Model Projected FS'!C9 -> 12549.6 | D7: ='3 Model Projected FS'!D9 -> 17118.79 | E7: ='3 Model Projected FS'!E9 -> 20851.91 | F7: ='3 Model Projected FS'!F9 -> 26710.56 | G7: ='3 Model Projected FS'!G9 -> 30475.33 | H7: ='3 Model Projected FS'!H9 -> 37803.28 | I7: ='3 Model Projected FS'!I9 -> 46945.27
B8: Revenue Growth YoY | D8: =ROUND(D7/C7-1,3) -> 0.364 | E8: =ROUND(E7/D7-1,3) -> 0.218 | F8: =ROUND(F7/E7-1,3) -> 0.281 | G8: =ROUND(G7/F7-1,3) -> 0.141 | H8: =ROUND(H7/G7-1,3) -> 0.24 | I8: =ROUND(I7/H7-1,3) -> 0.242
B9: Cost of Goods Sold | C9: =ROUND(SUM('3 Model Projected FS'!C11:C13),2) -> 3259.49 | D9: =ROUND(SUM('3 Model Projected FS'!D11:D13),2) -> 4865.11 | E9: =ROUND(SUM('3 Model Projected FS'!E11:E13),2) -> 5654.56 | F9: =ROUND(SUM('3 Model Projected FS'!F11:F13),2) -> 7116.34 | G9: =ROUND(SUM('3 Model Projected FS'!G11:G13),2) -> 8069.75 | H9: =ROUND(SUM('3 Model Projected FS'!H11:H13),2) -> 10017.87 | I9: =ROUND(SUM('3 Model Projected FS'!I11:I13),2) -> 12299.66
B10: Gross Profit | C10: =ROUND(C7-SUM(C9:C9),2) -> 9290.11 | D10: =ROUND(D7-SUM(D9:D9),2) -> 12253.68 | E10: =ROUND(E7-SUM(E9:E9),2) -> 15197.35 | F10: =ROUND(F7-SUM(F9:F9),2) -> 19594.22 | G10: =ROUND(G7-SUM(G9:G9),2) -> 22405.58 | H10: =ROUND(H7-SUM(H9:H9),2) -> 27785.41 | I10: =ROUND(I7-SUM(I9:I9),2) -> 34645.61
B11: Gross Profit Margin | C11: =ROUND(C10/C7,3) -> 0.74 | D11: =ROUND(D10/D7,3) -> 0.716 | E11: =ROUND(E10/E7,3) -> 0.729 | F11: =ROUND(F10/F7,3) -> 0.734 | G11: =ROUND(G10/G7,3) -> 0.735 | H11: =ROUND(H10/H7,3) -> 0.735 | I11: =ROUND(I10/I7,3) -> 0.738
B12: Operating Expenses | C12: =ROUND(SUM('3 Model Projected FS'!C16,'3 Model Projected FS'!C18),2) -> 591.43 | D12: =ROUND(SUM('3 Model Projected FS'!D16,'3 Model Projected FS'!D18),2) -> 2729.24 | E12: =ROUND(SUM('3 Model Projected FS'!E16,'3 Model Projected FS'!E18),2) -> 4250.22 | F12: =ROUND(SUM('3 Model Projected FS'!F16,'3 Model Projected FS'!F18),2) -> 3843.12 | G12: =ROUND(SUM('3 Model Projected FS'!G16,'3 Model Projected FS'!G18),2) -> 4265.06 | H12: =ROUND(SUM('3 Model Projected FS'!H16,'3 Model Projected FS'!H18),2) -> 5103.45 | I12: =ROUND(SUM('3 Model Projected FS'!I16,'3 Model Projected FS'!I18),2) -> 6431.5
B13: Loss on fair valuation of Compulsorily Convertible Preference Shares | C13: ='3 Model Projected FS'!C17 -> 0 | D13: ='3 Model Projected FS'!D17 -> 0 | E13: ='3 Model Projected FS'!E17 -> 0 | F13: ='3 Model Projected FS'!F17 -> 0 | G13: ='3 Model Projected FS'!G17 -> 0 | H13: ='3 Model Projected FS'!H17 -> 0 | I13: ='3 Model Projected FS'!I17 -> 0
B14: EBITDA | C14: =ROUND(C10-SUM(C12:C13),2) -> 8698.68 | D14: =ROUND(D10-SUM(D12:D13),2) -> 9524.44 | E14: =ROUND(E10-SUM(E12:E13),2) -> 10947.13 | F14: =ROUND(F10-SUM(F12:F13),2) -> 15751.1 | G14: =ROUND(G10-SUM(G12:G13),2) -> 18140.52 | H14: =ROUND(H10-SUM(H12:H13),2) -> 22681.96 | I14: =ROUND(I10-SUM(I12:I13),2) -> 28214.11
B15: EBITDA Margin | C15: =ROUND(C14/C7,3) -> 0.693 | D15: =ROUND(D14/D7,3) -> 0.556 | E15: =ROUND(E14/E7,3) -> 0.525 | F15: =ROUND(F14/F7,3) -> 0.59 | G15: =ROUND(G14/G7,3) -> 0.595 | H15: =ROUND(H14/H7,3) -> 0.6 | I15: =ROUND(I14/I7,3) -> 0.601
B16: Depreciation and Amortisation Expense | C16: ='3 Model Projected FS'!C21 -> 2107.34 | D16: ='3 Model Projected FS'!D21 -> 3099.3 | E16: ='3 Model Projected FS'!E21 -> 3423.24 | F16: ='3 Model Projected FS'!F21 -> 3888.46 | G16: ='3 Model Projected FS'!G21 -> 4378.93 | H16: ='3 Model Projected FS'!H21 -> 5229.0037 | I16: ='3 Model Projected FS'!I21 -> 5925.2319
B17: EBIT | C17: =ROUND(C14-C16,2) -> 6591.34 | D17: =ROUND(D14-D16,2) -> 6425.14 | E17: =ROUND(E14-E16,2) -> 7523.89 | F17: =ROUND(F14-F16,2) -> 11862.64 | G17: =ROUND(G14-G16,2) -> 13761.59 | H17: =ROUND(H14-H16,2) -> 17452.96 | I17: =ROUND(I14-I16,2) -> 22288.88
B18: Finance Costs | C18: ='3 Model Projected FS'!C23 -> 2255.29 | D18: ='3 Model Projected FS'!D23 -> 2543.92 | E18: ='3 Model Projected FS'!E23 -> 2362.64 | F18: ='3 Model Projected FS'!F23 -> 2732.94 | G18: ='3 Model Projected FS'!G23 -> 2531.82 | H18: ='3 Model Projected FS'!H23 -> 3063.5022 | I18: ='3 Model Projected FS'!I23 -> 3706.8377
B19: Other Income | C19: ='3 Model Projected FS'!C24 -> 1970.23 | D19: ='3 Model Projected FS'!D24 -> 2223.72 | E19: ='3 Model Projected FS'!E24 -> 1553.48 | F19: ='3 Model Projected FS'!F24 -> 1499.42 | G19: ='3 Model Projected FS'!G24 -> 1907.75 | H19: ='3 Model Projected FS'!H24 -> 2268.2 | I19: ='3 Model Projected FS'!I24 -> 2910.61
B20: Profit before share of Profit / (Loss) of Associate / Joint Ventures | C20: =ROUND(C17-C18+C19,2) -> 6306.28 | D20: =ROUND(D17-D18+D19,2) -> 6104.94 | E20: =ROUND(E17-E18+E19,2) -> 6714.73 | F20: =ROUND(F17-F18+F19,2) -> 10629.12 | G20: =ROUND(G17-G18+G19,2) -> 13137.52 | H20: =ROUND(H17-H18+H19,2) -> 16657.66 | I20: =ROUND(I17-I18+I19,2) -> 21492.65
B21: Share of Profit / (Loss) from Associate /Joint Ventures (net of tax) | C21: ='3 Model Projected FS'!C26 -> -14.27 | D21: ='3 Model Projected FS'!D26 -> 17.39 | E21: ='3 Model Projected FS'!E26 -> 47.78 | F21: ='3 Model Projected FS'!F26 -> -161.69 | G21: ='3 Model Projected FS'!G26 -> 141.56 | H21: ='3 Model Projected FS'!H26 -> 0 | I21: ='3 Model Projected FS'!I26 -> 0
B22: Profit before Exceptional Items and Tax | C22: =ROUND(SUM(C20:C21),2) -> 6292.01 | D22: =ROUND(D19-D21,2) -> 2206.33 | E22: =ROUND(SUM(E20:E21),2) -> 6762.51 | F22: =ROUND(SUM(F20:F21),2) -> 10467.43 | G22: =ROUND(SUM(G20:G21),2) -> 13279.08 | H22: =ROUND(SUM(H20:H21),2) -> 16657.66 | I22: =ROUND(SUM(I20:I21),2) -> 21492.65
B23: Exceptional Items | C23: ='3 Model Projected FS'!C28 -> 0 | D23: ='3 Model Projected FS'!D28 -> -405.19 | E23: ='3 Model Projected FS'!E28 -> -1273.38 | F23: ='3 Model Projected FS'!F28 -> -373.7 | G23: ='3 Model Projected FS'!G28 -> -249.46 | H23: ='3 Model Projected FS'!H28 -> -37.8 | I23: ='3 Model Projected FS'!I28 -> -46.95
B24: Profit before Tax | C24: =ROUND(SUM(C22:C23),2) -> 6292.01 | D24: =ROUND(SUM(D22:D23),2) -> 1801.14 | E24: =ROUND(SUM(E22:E23),2) -> 5489.13 | F24: =ROUND(SUM(F22:F23),2) -> 10093.73 | G24: =ROUND(SUM(G22:G23),2) -> 13029.62 | H24: =ROUND(SUM(H22:H23),2) -> 16619.86 | I24: =ROUND(SUM(I22:I23),2) -> 21445.7
B25: Tax | C25: ='3 Model Projected FS'!C30 -> 1243.27 | D25: ='3 Model Projected FS'!D30 -> 763.96 | E25: ='3 Model Projected FS'!E30 -> 96.38 | F25: ='3 Model Projected FS'!F30 -> 1989.74 | G25: ='3 Model Projected FS'!G30 -> 1968.36 | H25: ='3 Model Projected FS'!H30 -> 2659.18 | I25: ='3 Model Projected FS'!I30 -> 3431.31
B26: Tax Burden | C26: =ROUND(C25/C24,3) -> 0.198 | D26: =ROUND(D25/D24,3) -> 0.424 | E26: =ROUND(E25/E24,3) -> 0.018 | F26: =ROUND(F25/F24,3) -> 0.197 | G26: =ROUND(G25/G24,3) -> 0.151 | H26: =ROUND(H25/H24,3) -> 0.16 | I26: =ROUND(I25/I24,3) -> 0.16
B27: Net Profit | C27: ='3 Model Projected FS'!C36 -> 5048.74 | D27: ='3 Model Projected FS'!D36 -> 4953.18 | E27: ='3 Model Projected FS'!E36 -> 5392.75 | F27: ='3 Model Projected FS'!F36 -> 8103.99 | G27: ='3 Model Projected FS'!G36 -> 11061.26 | H27: ='3 Model Projected FS'!H36 -> 13960.68 | I27: ='3 Model Projected FS'!I36 -> 18014.39
B28: Net Profit Margin | C28: =ROUND(C27/C7,3) -> 0.402 | D28: =ROUND(D27/D7,3) -> 0.289 | E28: =ROUND(E27/E7,3) -> 0.259 | F28: =ROUND(F27/F7,3) -> 0.303 | G28: =ROUND(G27/G7,3) -> 0.363 | H28: =ROUND(H27/H7,3) -> 0.369 | I28: =ROUND(I27/I7,3) -> 0.384
B29: Net Profit attributable to:
B30: Owners of the company | C30: ='3 Model Projected FS'!C39 -> 4994.3 | D30: ='3 Model Projected FS'!D39 -> 4886.03 | E30: ='3 Model Projected FS'!E39 -> 5310.18 | F30: ='3 Model Projected FS'!F39 -> 8110.64 | G30: ='3 Model Projected FS'!G39 -> 11092.31 | H30: ='3 Model Projected FS'!H39 -> 13999.87 | I30: ='3 Model Projected FS'!I39 -> 18064.96
B31: Non-Controlling Interest | C31: ='3 Model Projected FS'!C40 -> 54.44 | D31: ='3 Model Projected FS'!D40 -> 67.15 | E31: ='3 Model Projected FS'!E40 -> 82.57 | F31: ='3 Model Projected FS'!F40 -> -6.65 | G31: ='3 Model Projected FS'!G40 -> -31.05 | H31: ='3 Model Projected FS'!H40 -> -39.19 | I31: ='3 Model Projected FS'!I40 -> -50.57
A33: # | B33: Balance Sheet
B35: ASSETS
B36: Non-current Assets
B37: Property, Plant and Equipment | C37: ='3 Model Projected FS'!C46 -> 36791.51 | D37: ='3 Model Projected FS'!D46 -> 41488.7 | E37: ='3 Model Projected FS'!E46 -> 48414 | F37: ='3 Model Projected FS'!F46 -> 51803.83 | G37: ='3 Model Projected FS'!G46 -> 62394.43 | H37: ='3 Model Projected FS'!H46 -> 74595.961 | I37: ='3 Model Projected FS'!I46 -> 84528.219
B38: Right of Use Assets | C38: ='3 Model Projected FS'!C47 -> 1775.95 | D38: ='3 Model Projected FS'!D47 -> 2772.25 | E38: ='3 Model Projected FS'!E47 -> 3541.9 | F38: ='3 Model Projected FS'!F47 -> 3809.11 | G38: ='3 Model Projected FS'!G47 -> 6177.54 | H38: ='3 Model Projected FS'!H47 -> 7385.5877 | I38: ='3 Model Projected FS'!I47 -> 8368.9595
B39: Capital work-in-progress | C39: ='3 Model Projected FS'!C48 -> 3697.13 | D39: ='3 Model Projected FS'!D48 -> 4022.9 | E39: ='3 Model Projected FS'!E48 -> 6814.03 | F39: ='3 Model Projected FS'!F48 -> 10936.09 | G39: ='3 Model Projected FS'!G48 -> 11592.19 | H39: ='3 Model Projected FS'!H48 -> 7454.473 | I39: ='3 Model Projected FS'!I48 -> 9318.0912
B40: Investment Property | C40: ='3 Model Projected FS'!C49 -> 0 | D40: ='3 Model Projected FS'!D49 -> 0 | E40: ='3 Model Projected FS'!E49 -> 2473.38 | F40: ='3 Model Projected FS'!F49 -> 1345.3 | G40: ='3 Model Projected FS'!G49 -> 1459.16 | H40: ='3 Model Projected FS'!H49 -> 1744.5058 | I40: ='3 Model Projected FS'!I49 -> 1976.7822
B41: Goodwill | C41: ='3 Model Projected FS'!C50 -> 4036.43 | D41: ='3 Model Projected FS'!D50 -> 6711.43 | E41: ='3 Model Projected FS'!E50 -> 6963.4 | F41: ='3 Model Projected FS'!F50 -> 6906.93 | G41: ='3 Model Projected FS'!G50 -> 7093.59 | H41: ='3 Model Projected FS'!H50 -> 7093.59 | I41: ='3 Model Projected FS'!I50 -> 7093.59
B42: Other Intangible Assets | C42: ='3 Model Projected FS'!C51 -> 5533.03 | D42: ='3 Model Projected FS'!D51 -> 11580.54 | E42: ='3 Model Projected FS'!E51 -> 11445.51 | F42: ='3 Model Projected FS'!F51 -> 11282.64 | G42: ='3 Model Projected FS'!G51 -> 12491.6 | H42: ='3 Model Projected FS'!H51 -> 113.91 | I42: ='3 Model Projected FS'!I51 -> 113.91
B43: Intangible Assets under Development | C43: ='3 Model Projected FS'!C52 -> 0 | D43: ='3 Model Projected FS'!D52 -> 0 | E43: ='3 Model Projected FS'!E52 -> 0 | F43: ='3 Model Projected FS'!F52 -> 0 | G43: ='3 Model Projected FS'!G52 -> 113.91 | H43: ='3 Model Projected FS'!H52 -> 113.91 | I43: ='3 Model Projected FS'!I52 -> 113.91
B44: Other Non-Current Assets | C44: =ROUND(SUM('3 Model Projected FS'!C53:C59),2) -> 10659.09 | D44: =ROUND(SUM('3 Model Projected FS'!D53:D59),2) -> 15021.58 | E44: =ROUND(SUM('3 Model Projected FS'!E53:E59),2) -> 17805.39 | F44: =ROUND(SUM('3 Model Projected FS'!F53:F59),2) -> 15361.61 | G44: =ROUND(SUM('3 Model Projected FS'!G53:G59),2) -> 15065.69 | H44: =ROUND(SUM('3 Model Projected FS'!H53:H59),2) -> 15065.69 | I44: =ROUND(SUM('3 Model Projected FS'!I53:I59),2) -> 15065.69
...

Sheet Scenarios
L1: ="Currently Running: "&IF(C6=1,"Base Case Scenario",IF(C6=2,"Bull Case Scenario","Bear Case Scenario")) -> Currently Running: Base Case Scenario
B2: SCENARIOS
B3: ₹'cr, unless otherwise stated | F3: ='[2]3 Model Projected FS'!C3 -> FY21A | G3: ='[2]3 Model Projected FS'!D3 -> FY22A | H3: ='[2]3 Model Projected FS'!E3 -> FY23A | I3: ='[2]3 Model Projected FS'!F3 -> FY24A | J3: ='[2]3 Model Projected FS'!G3 -> FY25A | K3: ='[2]3 Model Projected FS'!H3 -> FY26E | L3: ='[2]3 Model Projected FS'!I3 -> FY27E
A6: # | B6: SCENARIO SWITCH: | C6: 1
A9: # | B9: REVENUE SCHEDULE
B11: Total Consolidated Revenue | I11: =SUM(I14,I95,I107,I119,I131,I143) -> 26710.56 | J11: =SUM(J14,J95,J107,J119,J131,J143) -> 30475.33 | K11: =SUM(K14,K95,K107,K119,K131,K143) -> 37803.28 | L11: =SUM(L14,L95,L107,L119,L131,L143) -> 46945.27
B12: YoY growth rate | J12: =ROUND(J11/I11-1,3) -> 0.141 | K12: =ROUND(K11/J11-1,3) -> 0.24 | L12: =ROUND(L11/K11-1,3) -> 0.242
B14: Total Standalone Revenue | I14: =SUM(I31,I47,I63,I79) -> 26710.56 | J14: =SUM(J31,J47,J63,J79) -> 30475.33 | K14: =SUM(K31,K47,K63,K79) -> 37803.28 | L14: =SUM(L31,L47,L63,L79) -> 46945.27
B15: YoY growth rate | J15: =ROUND(J14/I14-1,3) -> 0.141 | K15: =ROUND(K14/J14-1,3) -> 0.24 | L15: =ROUND(L14/K14-1,3) -> 0.242
B17: Net Profit | F17: ='Consol. Historical FS'!C30 -> 5048.74 | G17: ='Consol. Historical FS'!D30 -> 4953.18 | H17: ='Consol. Historical FS'!E30 -> 5392.75 | I17: ='Consol. Historical FS'!F30 -> 8103.99 | J17: ='Consol. Historical FS'!G30 -> 11061.26 | K17: =ROUND(K14*K21,2) -> 3137.67 | L17: =ROUND(L14*L21,2) -> 3896.46
B19: Net Profit Margin
B21: Net Profit Margin | F21: ='Consol. Common Size FS'!C28 -> 0.402 | G21: ='Consol. Common Size FS'!D28 -> 0.289 | H21: ='Consol. Common Size FS'!E28 -> 0.259 | I21: ='Consol. Common Size FS'!F28 -> 0.303 | J21: ='Consol. Common Size FS'!G28 -> 0.363 | K21: =CHOOSE($C$6,K23,K24,K25) -> 0.083 | L21: =CHOOSE($C$6,L23,L24,L25) -> 0.083
B23: Base Case | K23: 0.083 | L23: 0.083
B24: Bull Case | C24: ="+1%" -> +1% | K24: =K23+$C24 -> 0.093 | L24: =L23+$C24 -> 0.093
B25: Bear Case | C25: ="-1%" -> -1% | K25: =K23+$C25 -> 0.073 | L25: =L23+$C25 -> 0.073
B27: Ports
B29: Revenue from Operations | I29: =3152+413+20343 -> 23908 | J29: =3380+933+22740 -> 27053
B30: Other Operating Revenues | I30: 0 | J30: 0
B31: Total Revenue | I31: =SUM(I29:I30) -> 23908 | J31: =SUM(J29:J30) -> 27053 | K31: =ROUND(J31*(1+K36),2) -> 32463.6 | L31: =ROUND(K31*(1+L36),2) -> 38956.32
B33: Growth Rate
B34: Revenue from Operations
B35: Other Operating Revenues
B36: Total Revenue | J36: =ROUND(J31/I31-1,3) -> 0.132 | K36: =CHOOSE($C$6,K39,K40,K41) -> 0.2 | L36: =CHOOSE($C$6,L39,L40,L41) -> 0.2
B38: Total Revenue
B39: =B23 -> Base Case | K39: 0.2 | L39: 0.2
B40: =B24 -> Bull Case | C40: ="+3%" -> +3% | K40: =K39+$C40 -> 0.23 | L40: =L39+$C40 -> 0.23
B41: =B25 -> Bear Case | C41: ="-3%" -> -3% | K41: =K39+$C41 -> 0.17 | L41: =L39+$C41 -> 0.17
B43: Logistics
B45: Revenue from Operations | I45: 2079 | J45: 2881
B46: Other Operating Revenues | I46: 0 | J46: 0
B47: Total Revenue | I47: =SUM(I45:I46) -> 2079 | J47: =SUM(J45:J46) -> 2881 | K47: =ROUND(J47*(1+K52),2) -> 4091.02 | L47: =ROUND(K47*(1+L52),2) -> 5727.43
B49: Growth Rate
B50: Revenue from Operations
B51: Other Operating Revenues
B52: Total Revenue | J52: =ROUND(J47/I47-1,3) -> 0.386 | K52: =CHOOSE($C$6,K55,K56,K57) -> 0.42 | L52: =CHOOSE($C$6,L55,L56,L57) -> 0.4
B54: Total Revenue
B55: =B39 -> Base Case | K55: 0.42 | L55: 0.4
B56: =B40 -> Bull Case | C56: ="+10%" -> +10% | K56: =K55+$C56 -> 0.52 | L56: =L55+$C56 -> 0.5
B57: =B41 -> Bear Case | C57: ="-8%" -> -8% | K57: =K55+$C57 -> 0.34 | L57: =L55+$C57 -> 0.32
B59: Marine
...

Sheet Other Data
A13: Other Data -->>

Sheet Graphs
H1: =[2]Scenarios!L1 -> Currently Running: Base Case Scenario
B2: CONSOLIDATED - GRAPHS
B3: ₹'cr, unless otherwise stated | C3: ='[2]3 Model Projected FS'!D3 -> FY22A | D3: ='[2]3 Model Projected FS'!E3 -> FY23A | E3: ='[2]3 Model Projected FS'!F3 -> FY24A | F3: ='[2]3 Model Projected FS'!G3 -> FY25A | G3: ='[2]3 Model Projected FS'!H3 -> FY26E | H3: ='[2]3 Model Projected FS'!I3 -> FY27E
B4: Revenue | C4: ='[2]3 Model Projected FS'!D9 -> 0 | D4: ='3 Model Projected FS'!E9 -> 20851.91 | E4: ='3 Model Projected FS'!F9 -> 26710.56 | F4: ='3 Model Projected FS'!G9 -> 30475.33 | G4: ='3 Model Projected FS'!H9 -> 37803.28 | H4: ='3 Model Projected FS'!I9 -> 46945.27
B5: EBITDA | D5: ='3 Model Projected FS'!E19 -> 10947.13 | E5: ='3 Model Projected FS'!F19 -> 15751.1 | F5: ='3 Model Projected FS'!G19 -> 18140.52 | G5: ='3 Model Projected FS'!H19 -> 22681.96 | H5: ='3 Model Projected FS'!I19 -> 28214.11
B6: Net Profit | D6: ='3 Model Projected FS'!E36 -> 5392.75 | E6: ='3 Model Projected FS'!F36 -> 8103.99 | F6: ='3 Model Projected FS'!G36 -> 11061.26 | G6: ='3 Model Projected FS'!H36 -> 13960.68 | H6: ='3 Model Projected FS'!I36 -> 18014.39
B7: Free Cash Flow | D7: ='3 Model Projected FS'!E156+'3 Model Projected FS'!E159 -> 3357.47 | E7: ='3 Model Projected FS'!F156+'3 Model Projected FS'!F159 -> 9637.91 | F7: ='3 Model Projected FS'!G156+'3 Model Projected FS'!G159 -> 8911.36 | G7: ='3 Model Projected FS'!H156+'3 Model Projected FS'!H159 -> 12985.298 | H7: ='3 Model Projected FS'!I156+'3 Model Projected FS'!I159 -> 16414.47
B8: Turnover Ratios
B9: Gross Fixed Assets | C9: ='[2]PP&E'!J13+'[2]Intangible Assets'!M13 -> 0 | D9: ='Summary_3 Model Projected FS'!E37+'Summary_3 Model Projected FS'!E38+'Summary_3 Model Projected FS'!E39+'Summary_3 Model Projected FS'!E40+'Summary_3 Model Projected FS'!E41+'Summary_3 Model Projected FS'!E42 -> 79652.22 | E9: ='Summary_3 Model Projected FS'!F37+'Summary_3 Model Projected FS'!F38+'Summary_3 Model Projected FS'!F39+'Summary_3 Model Projected FS'!F40+'Summary_3 Model Projected FS'!F41+'Summary_3 Model Projected FS'!F42 -> 86083.9 | F9: ='Summary_3 Model Projected FS'!G37+'Summary_3 Model Projected FS'!G38+'Summary_3 Model Projected FS'!G39+'Summary_3 Model Projected FS'!G40+'Summary_3 Model Projected FS'!G41+'Summary_3 Model Projected FS'!G42 -> 101208.51 | G9: ='Summary_3 Model Projected FS'!H37+'Summary_3 Model Projected FS'!H38+'Summary_3 Model Projected FS'!H39+'Summary_3 Model Projected FS'!H40+'Summary_3 Model Projected FS'!H41+'Summary_3 Model Projected FS'!H42 -> 98388.027 | H9: ='Summary_3 Model Projected FS'!I37+'Summary_3 Model Projected FS'!I38+'Summary_3 Model Projected FS'!I39+'Summary_3 Model Projected FS'!I40+'Summary_3 Model Projected FS'!I41+'Summary_3 Model Projected FS'!I42 -> 111399.55
B10: GFAT | C10: =ROUND(C4/AVERAGE(B9:C9),1) -> #DIV/0! | D10: =ROUND(D4/AVERAGE(C9:D9),1) -> 0.5 | E10: =ROUND(E4/AVERAGE(D9:E9),1) -> 0.3 | F10: =ROUND(F4/AVERAGE(E9:F9),1) -> 0.3 | G10: =ROUND(G4/AVERAGE(F9:G9),1) -> 0.4 | H10: =ROUND(H4/AVERAGE(G9:H9),1) -> 0.4
B11: ITR | D11: =ROUND(SUM('3 Model Projected FS'!E11:E13)/AVERAGE('3 Model Projected FS'!D63:E63),1) -> 13.3 | E11: =ROUND(SUM('3 Model Projected FS'!F11:F13)/AVERAGE('3 Model Projected FS'!E63:F63),1) -> 16 | F11: =ROUND(SUM('3 Model Projected FS'!G11:G13)/AVERAGE('3 Model Projected FS'!F63:G63),1) -> 16.8 | G11: =ROUND(SUM('3 Model Projected FS'!H11:H13)/AVERAGE('3 Model Projected FS'!G63:H63),1) -> 17.4 | H11: =ROUND(SUM('3 Model Projected FS'!I11:I13)/AVERAGE('3 Model Projected FS'!H63:I63),1) -> 17.5
B12: RTR | D12: =ROUND('3 Model Projected FS'!E9/AVERAGE('3 Model Projected FS'!D66:E66),1) -> 7.6 | E12: =ROUND('3 Model Projected FS'!F9/AVERAGE('3 Model Projected FS'!E66:F66),1) -> 7.7 | F12: =ROUND('3 Model Projected FS'!G9/AVERAGE('3 Model Projected FS'!F66:G66),1) -> 7.5 | G12: =ROUND('3 Model Projected FS'!H9/AVERAGE('3 Model Projected FS'!G66:H66),1) -> 8 | H12: =ROUND('3 Model Projected FS'!I9/AVERAGE('3 Model Projected FS'!H66:I66),1) -> 8.5
B13: Profit Margin Ratios
B14: EBITDA Margin | D14: ='3 Model Projected FS'!E20 -> 0.525 | E14: ='3 Model Projected FS'!F20 -> 0.59 | F14: ='3 Model Projected FS'!G20 -> 0.595 | G14: ='3 Model Projected FS'!H20 -> 0.6 | H14: ='3 Model Projected FS'!I20 -> 0.601
B15: Net Profit Margin | D15: ='3 Model Projected FS'!E37 -> 0.259 | E15: ='3 Model Projected FS'!F37 -> 0.303 | F15: ='3 Model Projected FS'!G37 -> 0.363 | G15: ='3 Model Projected FS'!H37 -> 0.369 | H15: ='3 Model Projected FS'!I37 -> 0.384
